<mujoco model="ur5e_manipulation_scene">
  <compiler angle="radian" meshdir="mujoco_menagerie" autolimits="true"/>
  
  <option integrator="implicitfast" timestep="0.002"/>
  
  <statistic center="0.5 0 0.4" extent="1.2"/>
  
  <visual>
    <headlight diffuse="0.6 0.6 0.6" ambient="0.3 0.3 0.3" specular="0.1 0.1 0.1"/>
    <rgba haze="0.15 0.25 0.35 1"/>
    <global azimuth="120" elevation="-20"/>
    <quality shadowsize="2048"/>
    <map stiffness="700" shadowscale="0.5" fogstart="10" fogend="15"/>
  </visual>
  
  <default>
    <default class="ur5e">
      <material specular="0.5" shininess="0.25"/>
      <joint axis="0 1 0" range="-6.28319 6.28319" armature="0.1" damping="10"/>
      <general gaintype="fixed" biastype="affine" ctrlrange="-6.2831 6.2831" gainprm="5000" biasprm="0 -5000 -1000"
        forcerange="-400 400"/>
      <default class="size3">
        <default class="size3_limited">
          <joint range="-3.1415 3.1415"/>
          <general ctrlrange="-3.1415 3.1415"/>
        </default>
      </default>
      <default class="size1">
        <general gainprm="1000" biasprm="0 -1000 -200" forcerange="-60 60"/>
      </default>
      <default class="visual">
        <geom type="mesh" contype="0" conaffinity="0" group="2"/>
      </default>
      <default class="collision">
        <geom type="capsule" group="3"/>
        <default class="eef_collision">
          <geom type="cylinder"/>
        </default>
      </default>
      <site size="0.001" rgba="0.5 0.5 0.5 0.3" group="4"/>
    </default>
  </default>
  
  <asset>
    <!-- UR5e materials -->
    <material class="ur5e" name="black" rgba="0.033 0.033 0.033 1"/>
    <material class="ur5e" name="jointgray" rgba="0.278 0.278 0.278 1"/>
    <material class="ur5e" name="linkgray" rgba="0.82 0.82 0.82 1"/>
    <material class="ur5e" name="urblue" rgba="0.49 0.678 0.8 1"/>
    
    <!-- Robotiq 2F-85 gripper materials -->
    <material name="metal" rgba="0.58 0.58 0.58 1"/>
    <material name="silicone" rgba="0.1882 0.1882 0.1882 1"/>
    <material name="gray" rgba="0.4627 0.4627 0.4627 1"/>
    <material name="robotiq_black" rgba="0.149 0.149 0.149 1"/>
    
    <!-- Environment materials -->
    <texture type="skybox" builtin="gradient" rgb1="0.3 0.5 0.7" rgb2="0 0 0" width="512" height="3072"/>
    <texture type="2d" name="groundplane" builtin="checker" mark="edge" rgb1="0.2 0.3 0.4" rgb2="0.1 0.2 0.3"
      markrgb="0.8 0.8 0.8" width="300" height="300"/>
    <material name="groundplane" texture="groundplane" texuniform="true" texrepeat="5 5" reflectance="0.2"/>
    
    <!-- Table material -->
    <material name="table" rgba="0.7 0.5 0.3 1"/>
    
    <!-- Object materials -->
    <material name="red_cube" rgba="0.8 0.2 0.2 1"/>
    <material name="green_cube" rgba="0.2 0.8 0.2 1"/>
    <material name="blue_cube" rgba="0.2 0.2 0.8 1"/>
    <material name="yellow_sphere" rgba="0.9 0.9 0.2 1"/>
    <material name="cyan_cylinder" rgba="0.2 0.9 0.9 1"/>
    
    <!-- UR5e meshes -->
    <mesh file="universal_robots_ur5e/assets/base_0.obj"/>
    <mesh file="universal_robots_ur5e/assets/base_1.obj"/>
    <mesh file="universal_robots_ur5e/assets/shoulder_0.obj"/>
    <mesh file="universal_robots_ur5e/assets/shoulder_1.obj"/>
    <mesh file="universal_robots_ur5e/assets/shoulder_2.obj"/>
    <mesh file="universal_robots_ur5e/assets/upperarm_0.obj"/>
    <mesh file="universal_robots_ur5e/assets/upperarm_1.obj"/>
    <mesh file="universal_robots_ur5e/assets/upperarm_2.obj"/>
    <mesh file="universal_robots_ur5e/assets/upperarm_3.obj"/>
    <mesh file="universal_robots_ur5e/assets/forearm_0.obj"/>
    <mesh file="universal_robots_ur5e/assets/forearm_1.obj"/>
    <mesh file="universal_robots_ur5e/assets/forearm_2.obj"/>
    <mesh file="universal_robots_ur5e/assets/forearm_3.obj"/>
    <mesh file="universal_robots_ur5e/assets/wrist1_0.obj"/>
    <mesh file="universal_robots_ur5e/assets/wrist1_1.obj"/>
    <mesh file="universal_robots_ur5e/assets/wrist1_2.obj"/>
    <mesh file="universal_robots_ur5e/assets/wrist2_0.obj"/>
    <mesh file="universal_robots_ur5e/assets/wrist2_1.obj"/>
    <mesh file="universal_robots_ur5e/assets/wrist2_2.obj"/>
    <mesh file="universal_robots_ur5e/assets/wrist3.obj"/>
    
    <!-- Robotiq 2F-85 gripper meshes -->
    <mesh name="gripper_base_mount" file="robotiq_2f85/assets/base_mount.stl" scale="0.001 0.001 0.001"/>
    <mesh name="gripper_base" file="robotiq_2f85/assets/base.stl" scale="0.001 0.001 0.001"/>
    <mesh name="gripper_driver" file="robotiq_2f85/assets/driver.stl" scale="0.001 0.001 0.001"/>
    <mesh name="gripper_coupler" file="robotiq_2f85/assets/coupler.stl" scale="0.001 0.001 0.001"/>
    <mesh name="gripper_follower" file="robotiq_2f85/assets/follower.stl" scale="0.001 0.001 0.001"/>
    <mesh name="gripper_pad" file="robotiq_2f85/assets/pad.stl" scale="0.001 0.001 0.001"/>
    <mesh name="gripper_silicone_pad" file="robotiq_2f85/assets/silicone_pad.stl" scale="0.001 0.001 0.001"/>
    <mesh name="gripper_spring_link" file="robotiq_2f85/assets/spring_link.stl" scale="0.001 0.001 0.001"/>
  </asset>
  
  <worldbody>
    <!-- Lighting -->
    <light name="top_light" pos="0.5 0 2" dir="0 0 -1" directional="true" diffuse="0.8 0.8 0.8"/>
    <light name="side_light" pos="1 1 1.5" dir="-0.5 -0.5 -1" directional="true" diffuse="0.4 0.4 0.4"/>
    
    <!-- Floor -->
    <geom name="floor" size="0 0 0.05" type="plane" material="groundplane"/>
    
    <!-- Cameras -->
    <camera name="external_camera_left" pos="1.0 0.8 1.2" xyaxes="-0.8 0.6 0 -0.3 -0.4 0.9" fovy="60"/>
    <!-- <camera name="external_camera_right" pos="1.0 -0.8 1.2" xyaxes="-0.8 -0.6 0 0.3 -0.4 0.9" fovy="60"/> -->
    <camera name="front_camera" pos="1.5 0 0.8" xyaxes="0 -1 0 0.5 0 1" fovy="60"/>
    
    <!-- Table -->
    <body name="table" pos="0.7 0 0">
      <geom name="table_top" type="box" size="0.4 0.5 0.025" pos="0 0 0.4" material="table"/>
      <geom name="table_leg1" type="cylinder" size="0.03 0.4" pos="0.3 0.4 0" rgba="0.5 0.3 0.1 1"/>
      <geom name="table_leg2" type="cylinder" size="0.03 0.4" pos="0.3 -0.4 0" rgba="0.5 0.3 0.1 1"/>
      <geom name="table_leg3" type="cylinder" size="0.03 0.4" pos="-0.3 0.4 0" rgba="0.5 0.3 0.1 1"/>
      <geom name="table_leg4" type="cylinder" size="0.03 0.4" pos="-0.3 -0.4 0" rgba="0.5 0.3 0.1 1"/>
    </body>
    
    <!-- UR5e Robot -->
    <body name="robot_base" pos="0 0 0.4" childclass="ur5e">
      <inertial mass="4.0" pos="0 0 0" diaginertia="0.00443333156 0.00443333156 0.0072"/>
      <geom mesh="base_0" material="black" class="visual"/>
      <geom mesh="base_1" material="jointgray" class="visual"/>
      <body name="shoulder_link" pos="0 0 0.163">
        <inertial mass="3.7" pos="0 0 0" diaginertia="0.0102675 0.0102675 0.00666"/>
        <joint name="shoulder_pan_joint" class="size3" axis="0 0 1"/>
        <geom mesh="shoulder_0" material="urblue" class="visual"/>
        <geom mesh="shoulder_1" material="black" class="visual"/>
        <geom mesh="shoulder_2" material="jointgray" class="visual"/>
        <geom class="collision" size="0.06 0.06" pos="0 0 -0.04"/>
        <body name="upper_arm_link" pos="0 0.138 0" quat="1 0 1 0">
          <inertial mass="8.393" pos="0 0 0.2125" diaginertia="0.133886 0.133886 0.0151074"/>
          <joint name="shoulder_lift_joint" class="size3"/>
          <geom mesh="upperarm_0" material="linkgray" class="visual"/>
          <geom mesh="upperarm_1" material="black" class="visual"/>
          <geom mesh="upperarm_2" material="jointgray" class="visual"/>
          <geom mesh="upperarm_3" material="urblue" class="visual"/>
          <geom class="collision" pos="0 -0.04 0" quat="1 1 0 0" size="0.06 0.06"/>
          <geom class="collision" size="0.05 0.2" pos="0 0 0.2"/>
          <body name="forearm_link" pos="0 -0.131 0.425">
            <inertial mass="2.275" pos="0 0 0.196" diaginertia="0.0311796 0.0311796 0.004095"/>
            <joint name="elbow_joint" class="size3_limited"/>
            <geom mesh="forearm_0" material="urblue" class="visual"/>
            <geom mesh="forearm_1" material="linkgray" class="visual"/>
            <geom mesh="forearm_2" material="black" class="visual"/>
            <geom mesh="forearm_3" material="jointgray" class="visual"/>
            <geom class="collision" pos="0 0.08 0" quat="1 1 0 0" size="0.055 0.06"/>
            <geom class="collision" size="0.038 0.19" pos="0 0 0.2"/>
            <body name="wrist_1_link" pos="0 0 0.392" quat="1 0 1 0">
              <inertial mass="1.219" pos="0 0.127 0" diaginertia="0.0025599 0.0025599 0.0021942"/>
              <joint name="wrist_1_joint" class="size1"/>
              <geom mesh="wrist1_0" material="black" class="visual"/>
              <geom mesh="wrist1_1" material="urblue" class="visual"/>
              <geom mesh="wrist1_2" material="jointgray" class="visual"/>
              <geom class="collision" pos="0 0.05 0" quat="1 1 0 0" size="0.04 0.07"/>
              <body name="wrist_2_link" pos="0 0.127 0">
                <inertial mass="1.219" pos="0 0 0.1" diaginertia="0.0025599 0.0025599 0.0021942"/>
                <joint name="wrist_2_joint" axis="0 0 1" class="size1"/>
                <geom mesh="wrist2_0" material="black" class="visual"/>
                <geom mesh="wrist2_1" material="urblue" class="visual"/>
                <geom mesh="wrist2_2" material="jointgray" class="visual"/>
                <geom class="collision" size="0.04 0.06" pos="0 0 0.04"/>
                <geom class="collision" pos="0 0.02 0.1" quat="1 1 0 0" size="0.04 0.04"/>
                <body name="wrist_3_link" pos="0 0 0.1">
                  <inertial mass="0.1889" pos="0 0.0771683 0" quat="1 0 0 1"
                    diaginertia="0.000132134 9.90863e-05 9.90863e-05"/>
                  <joint name="wrist_3_joint" class="size1"/>
                  <geom material="linkgray" mesh="wrist3" class="visual"/>
                  <geom class="eef_collision" pos="0 0.08 0" quat="1 1 0 0" size="0.04 0.02"/>
                  <site name="attachment_site" pos="0 0.1 0" quat="-1 1 0 0"/>
                  
                  <!-- Wrist camera mounted on end-effector -->
                  <camera name="wrist_camera" pos="0 0.1 0.05" xyaxes="1 0 0 0 0 1" fovy="100"/>
                  
                  <!-- Visual marker for wrist camera debugging -->
                  <!-- <body name="wrist_cam_marker" pos="0 0.1 0.05">
                    <geom type="sphere" size="0.015" rgba="1 1 0 0.8" contype="0" conaffinity="0"/>
                  </body>
                   -->
                  <!-- Robotiq 2F-85 Gripper -->
                  <body name="gripper_base_mount" pos="0 0.1 0" quat="0 0 0.707107 0.707107">
                    <inertial mass="0.777441" pos="0 -2.70394e-05 0.0354675" quat="1 -0.00152849 0 0"
                      diaginertia="0.000260285 0.000225381 0.000152708"/>
                    <geom type="mesh" mesh="gripper_base_mount" material="robotiq_black" contype="0" conaffinity="0" group="2"/>
                    <geom type="mesh" mesh="gripper_base_mount" group="3"/>
                    <body name="gripper_base" pos="0 0 0.0108" quat="1 0 0 -1">
                      <geom type="mesh" mesh="gripper_base" material="robotiq_black" contype="0" conaffinity="0" group="2"/>
                      <geom type="mesh" mesh="gripper_base" group="3"/>
                      <site name="pinch" pos="0 0 0.145" type="sphere" group="5" rgba="0.9 0.9 0.9 1" size="0.005"/>
                      
                      <!-- Right finger assembly -->
                      <body name="right_driver" pos="0 0.0306011 0.054904">
                        <inertial mass="0.00899563" pos="2.96931e-12 0.0177547 0.00107314" quat="0.681301 0.732003 0 0"
                          diaginertia="1.72352e-06 1.60906e-06 3.22006e-07"/>
                        <joint name="right_driver_joint" type="hinge" axis="1 0 0" range="0 0.8" armature="0.005" damping="0.1"/>
                        <geom type="mesh" mesh="gripper_driver" material="gray" contype="0" conaffinity="0" group="2"/>
                        <geom type="mesh" mesh="gripper_driver" group="3"/>
                        <body name="right_coupler" pos="0 0.0315 -0.0041">
                          <inertial mass="0.0140974" pos="0 0.00301209 0.0232175" quat="0.705636 -0.0455904 0.0455904 0.705636"
                            diaginertia="4.16206e-06 3.52216e-06 8.88131e-07"/>
                          <joint name="right_coupler_joint" type="hinge" axis="1 0 0" range="-1.57 0" armature="0.001"/>
                          <geom type="mesh" mesh="gripper_coupler" material="robotiq_black" contype="0" conaffinity="0" group="2"/>
                          <geom type="mesh" mesh="gripper_coupler" group="3"/>
                        </body>
                      </body>
                      <body name="right_spring_link" pos="0 0.0132 0.0609">
                        <inertial mass="0.0221642" pos="-8.65005e-09 0.0181624 0.0212658" quat="0.663403 -0.244737 0.244737 0.663403"
                          diaginertia="8.96853e-06 6.71733e-06 2.63931e-06"/>
                        <joint name="right_spring_link_joint" type="hinge" axis="1 0 0" range="-0.29670597283 0.8" stiffness="0.05" springref="2.62" damping="0.00125" armature="0.001"/>
                        <geom type="mesh" mesh="gripper_spring_link" material="robotiq_black" contype="0" conaffinity="0" group="2"/>
                        <geom type="mesh" mesh="gripper_spring_link" group="3"/>
                        <body name="right_follower" pos="0 0.055 0.0375">
                          <inertial mass="0.0125222" pos="0 -0.011046 0.0124786" quat="1 0.1664 0 0"
                            diaginertia="2.67415e-06 2.4559e-06 6.02031e-07"/>
                          <joint name="right_follower_joint" type="hinge" axis="1 0 0" range="-0.872664 0.872664" pos="0 -0.018 0.0065" armature="0.001"/>
                          <geom type="mesh" mesh="gripper_follower" material="robotiq_black" contype="0" conaffinity="0" group="2"/>
                          <geom type="mesh" mesh="gripper_follower" group="3"/>
                          <body name="right_pad" pos="0 -0.0189 0.01352">
                            <inertial mass="0.0035" pos="0 -0.0025 0.0185" quat="0.707107 0 0 0.707107"
                              diaginertia="4.73958e-07 3.64583e-07 1.23958e-07"/>
                            <geom type="mesh" mesh="gripper_pad" contype="0" conaffinity="0" group="2"/>
                            <geom type="box" pos="0 -0.0026 0.028125" size="0.011 0.004 0.009375" friction="0.7" rgba="0.55 0.55 0.55 1"/>
                            <geom type="box" pos="0 -0.0026 0.009375" size="0.011 0.004 0.009375" friction="0.6" rgba="0.45 0.45 0.45 1"/>
                            <body name="right_silicone_pad">
                              <geom type="mesh" mesh="gripper_silicone_pad" material="robotiq_black" contype="0" conaffinity="0" group="2"/>
                            </body>
                          </body>
                        </body>
                      </body>
                      
                      <!-- Left finger assembly (mirrored) -->
                      <body name="left_driver" pos="0 -0.0306011 0.054904" quat="0 0 0 1">
                        <inertial mass="0.00899563" pos="0 0.0177547 0.00107314" quat="0.681301 0.732003 0 0"
                          diaginertia="1.72352e-06 1.60906e-06 3.22006e-07"/>
                        <joint name="left_driver_joint" type="hinge" axis="1 0 0" range="0 0.8" armature="0.005" damping="0.1"/>
                        <geom type="mesh" mesh="gripper_driver" material="gray" contype="0" conaffinity="0" group="2"/>
                        <geom type="mesh" mesh="gripper_driver" group="3"/>
                        <body name="left_coupler" pos="0 0.0315 -0.0041">
                          <inertial mass="0.0140974" pos="0 0.00301209 0.0232175" quat="0.705636 -0.0455904 0.0455904 0.705636"
                            diaginertia="4.16206e-06 3.52216e-06 8.88131e-07"/>
                          <joint name="left_coupler_joint" type="hinge" axis="1 0 0" range="-1.57 0" armature="0.001"/>
                          <geom type="mesh" mesh="gripper_coupler" material="robotiq_black" contype="0" conaffinity="0" group="2"/>
                          <geom type="mesh" mesh="gripper_coupler" group="3"/>
                        </body>
                      </body>
                      <body name="left_spring_link" pos="0 -0.0132 0.0609" quat="0 0 0 1">
                        <inertial mass="0.0221642" pos="-8.65005e-09 0.0181624 0.0212658" quat="0.663403 -0.244737 0.244737 0.663403"
                          diaginertia="8.96853e-06 6.71733e-06 2.63931e-06"/>
                        <joint name="left_spring_link_joint" type="hinge" axis="1 0 0" range="-0.29670597283 0.8" stiffness="0.05" springref="2.62" damping="0.00125" armature="0.001"/>
                        <geom type="mesh" mesh="gripper_spring_link" material="robotiq_black" contype="0" conaffinity="0" group="2"/>
                        <geom type="mesh" mesh="gripper_spring_link" group="3"/>
                        <body name="left_follower" pos="0 0.055 0.0375">
                          <inertial mass="0.0125222" pos="0 -0.011046 0.0124786" quat="1 0.1664 0 0"
                            diaginertia="2.67415e-06 2.4559e-06 6.02031e-07"/>
                          <joint name="left_follower_joint" type="hinge" axis="1 0 0" range="-0.872664 0.872664" pos="0 -0.018 0.0065" armature="0.001"/>
                          <geom type="mesh" mesh="gripper_follower" material="robotiq_black" contype="0" conaffinity="0" group="2"/>
                          <geom type="mesh" mesh="gripper_follower" group="3"/>
                          <body name="left_pad" pos="0 -0.0189 0.01352">
                            <inertial mass="0.0035" pos="0 -0.0025 0.0185" quat="1 0 0 1"
                              diaginertia="4.73958e-07 3.64583e-07 1.23958e-07"/>
                            <geom type="mesh" mesh="gripper_pad" contype="0" conaffinity="0" group="2"/>
                            <geom type="box" pos="0 -0.0026 0.028125" size="0.011 0.004 0.009375" friction="0.7" rgba="0.55 0.55 0.55 1"/>
                            <geom type="box" pos="0 -0.0026 0.009375" size="0.011 0.004 0.009375" friction="0.6" rgba="0.45 0.45 0.45 1"/>
                            <body name="left_silicone_pad">
                              <geom type="mesh" mesh="gripper_silicone_pad" material="robotiq_black" contype="0" conaffinity="0" group="2"/>
                            </body>
                          </body>
                        </body>
                      </body>
                    </body>
                  </body>
                </body>
              </body>
            </body>
          </body>
        </body>
      </body>
    </body>
    
    <!-- Manipulable Objects on table -->
    <body name="red_cube" pos="0.7 0.15 0.45">
      <freejoint/>
      <inertial pos="0 0 0" mass="0.1" diaginertia="0.00016667 0.00016667 0.00016667"/>
      <geom name="red_cube_geom" type="box" size="0.03 0.03 0.03" material="red_cube" friction="1 0.5 0.5"/>
    </body>
    
    <body name="green_cube" pos="0.6 -0.1 0.45">
      <freejoint/>
      <inertial pos="0 0 0" mass="0.1" diaginertia="0.00016667 0.00016667 0.00016667"/>
      <geom name="green_cube_geom" type="box" size="0.03 0.03 0.03" material="green_cube" friction="1 0.5 0.5"/>
    </body>
    
    <body name="blue_cube" pos="0.8 -0.2 0.45">
      <freejoint/>
      <inertial pos="0 0 0" mass="0.1" diaginertia="0.00016667 0.00016667 0.00016667"/>
      <geom name="blue_cube_geom" type="box" size="0.03 0.03 0.03" material="blue_cube" friction="1 0.5 0.5"/>
    </body>
    
    <body name="yellow_sphere5708" pos="0.7 0 0.455">
      <freejoint/>
      <inertial pos="0 0 0" mass="0.08" diaginertia="0.0001536 0.0001536 0.0001536"/>
      <geom name="yellow_sphere_geom" type="sphere" size="0.025" material="yellow_sphere" friction="1 0.5 0.5"/>
    </body>
    
    <body name="cyan_cylinder" pos="0.8 0.2 0.45">
      <freejoint/>
      <inertial pos="0 0 0" mass="0.09" diaginertia="0.000135 0.000135 0.0000675"/>
      <geom name="cyan_cylinder_geom" type="cylinder" size="0.02 0.04" material="cyan_cylinder" friction="1 0.5 0.5"/>
    </body>
  </worldbody>
  
  <contact>
    <exclude body1="gripper_base" body2="left_driver"/>
    <exclude body1="gripper_base" body2="right_driver"/>
    <exclude body1="gripper_base" body2="left_spring_link"/>
    <exclude body1="gripper_base" body2="right_spring_link"/>
    <exclude body1="right_coupler" body2="right_follower"/>
    <exclude body1="left_coupler" body2="left_follower"/>
  </contact>
  
  <tendon>
    <fixed name="split">
      <joint joint="right_driver_joint" coef="0.5"/>
      <joint joint="left_driver_joint" coef="0.5"/>
    </fixed>
  </tendon>
  
  <equality>
    <connect anchor="0 0 0" body1="right_follower" body2="right_coupler" solimp="0.95 0.99 0.001" solref="0.005 1"/>
    <connect anchor="0 0 0" body1="left_follower" body2="left_coupler" solimp="0.95 0.99 0.001" solref="0.005 1"/>
    <joint joint1="right_driver_joint" joint2="left_driver_joint" polycoef="0 1 0 0 0" solimp="0.95 0.99 0.001" solref="0.005 1"/>
  </equality>
  
  <actuator>
    <!-- UR5 arm actuators -->
    <general class="size3" name="shoulder_pan" joint="shoulder_pan_joint"/>
    <general class="size3" name="shoulder_lift" joint="shoulder_lift_joint"/>
    <general class="size3_limited" name="elbow" joint="elbow_joint"/>
    <general class="size1" name="wrist_1" joint="wrist_1_joint"/>
    <general class="size1" name="wrist_2" joint="wrist_2_joint"/>
    <general class="size1" name="wrist_3" joint="wrist_3_joint"/>
    <!-- Robotiq gripper actuator -->
    <general name="fingers_actuator" tendon="split" forcerange="-5 5" ctrlrange="0 255" gainprm="0.3137255 0 0" biasprm="0 -100 -10"/>
  </actuator>
  
  <keyframe>
    <!-- Key pose: 6 arm joints + 8 gripper joints (robotiq) + 5 free objects (7 DOFs each: x y z qw qx qy qz) -->
    <!-- Gripper joints: right_driver, right_coupler, right_spring_link, right_follower, left_driver, left_coupler, left_spring_link, left_follower -->
    <key name="home" 
         qpos="0 -1.5708 1.5708 -1.5708 -1.5708 0
               0 0 0 0 0 0 0 0
               0.7 0.15 0.45 1 0 0 0
               0.6 -0.1 0.45 1 0 0 0
               0.8 -0.2 0.45 1 0 0 0
               0.7 0 0.455 1 0 0 0
               0.8 0.2 0.45 1 0 0 0" />
  </keyframe>
</mujoco>


